<?xml version="1.0" encoding="UTF-8"?>
<!-- Generated by org.testng.reporters.JUnitReportReporter -->
<testsuite hostname="DML-09303" failures="0" tests="4" name="TestNG0008AnnotationAttributes.SuiteName" time="0.013" errors="1" timestamp="18 Aug 2022 09:10:11 GMT" skipped="0">
  <testcase classname="TestNG0008AnnotationAttributes.SuiteName" name="exceptionTestOne" time="0.010"/>
  <testcase classname="TestNG0008AnnotationAttributes.SuiteName" name="exceptionTestThree" time="0.001">
    <error message="
The exception was thrown with the wrong message: expected &quot;Pass Message test&quot; but got &quot;Fail Message test&quot;" type="org.testng.TestException">
      <![CDATA[org.testng.TestException: 
The exception was thrown with the wrong message: expected "Pass Message test" but got "Fail Message test"
at org.testng.internal.ExpectedExceptionsHolder.wrongException(ExpectedExceptionsHolder.java:71)
at org.testng.internal.Invoker.considerExceptions(Invoker.java:1130)
at org.testng.internal.Invoker.invokeMethod(Invoker.java:615)
at org.testng.internal.Invoker.invokeTestMethod(Invoker.java:719)
at org.testng.internal.Invoker.invokeTestMethods(Invoker.java:989)
at org.testng.internal.TestMethodWorker.invokeTestMethods(TestMethodWorker.java:125)
at org.testng.internal.TestMethodWorker.run(TestMethodWorker.java:109)
at org.testng.TestRunner.privateRun(TestRunner.java:648)
at org.testng.TestRunner.run(TestRunner.java:505)
at org.testng.SuiteRunner.runTest(SuiteRunner.java:455)
at org.testng.SuiteRunner.runSequentially(SuiteRunner.java:450)
at org.testng.SuiteRunner.privateRun(SuiteRunner.java:415)
at org.testng.SuiteRunner.run(SuiteRunner.java:364)
at org.testng.SuiteRunnerWorker.runSuite(SuiteRunnerWorker.java:52)
at org.testng.SuiteRunnerWorker.run(SuiteRunnerWorker.java:84)
at org.testng.TestNG.runSuitesSequentially(TestNG.java:1208)
at org.testng.TestNG.runSuitesLocally(TestNG.java:1137)
at org.testng.TestNG.runSuites(TestNG.java:1049)
at org.testng.TestNG.run(TestNG.java:1017)
at org.testng.remote.AbstractRemoteTestNG.run(AbstractRemoteTestNG.java:115)
at org.testng.remote.RemoteTestNG.initAndRun(RemoteTestNG.java:251)
at org.testng.remote.RemoteTestNG.main(RemoteTestNG.java:77)
Caused by: java.io.IOException: Fail Message test
at TestNG0008AnnotationAttributes.SuiteName.exceptionTestThree(SuiteName.java:31)
at java.base/jdk.internal.reflect.NativeMethodAccessorImpl.invoke0(Native Method)
at java.base/jdk.internal.reflect.NativeMethodAccessorImpl.invoke(NativeMethodAccessorImpl.java:62)
at java.base/jdk.internal.reflect.DelegatingMethodAccessorImpl.invoke(DelegatingMethodAccessorImpl.java:43)
at java.base/java.lang.reflect.Method.invoke(Method.java:566)
at org.testng.internal.MethodInvocationHelper.invokeMethod(MethodInvocationHelper.java:124)
at org.testng.internal.Invoker.invokeMethod(Invoker.java:583)
... 19 more
]]>
    </error>
  </testcase> <!-- exceptionTestThree -->
  <testcase classname="TestNG0008AnnotationAttributes.SuiteName" name="exceptionTestTwo" time="0.001"/>
  <testcase classname="TestNG0008AnnotationAttributes.SuiteName" name="testPrintMessage" time="0.001"/>
</testsuite> <!-- TestNG0008AnnotationAttributes.SuiteName -->
